<?xml version="1.0" ?>
<!-- =================================================================================== -->
<!-- |    This document was autogenerated by xacro from irb2400.xacro                  | -->
<!-- |    EDITING THIS FILE BY HAND IS NOT RECOMMENDED                                 | -->
<!-- =================================================================================== -->
<robot name="abb_irb2400" xmlns:xacro="http://ros.org/wiki/xacro">
  <!-- Conversion were obtained from http://www.e-paint.co.uk/Lab_values.asp
       unless otherwise stated. -->
  <!-- Actual colors -->
  <!-- NCS 2070-Y60R orange, standard robot color 1974 - May 2014 -->
  <!-- RAL 7035 light grey (abb graphite white), standard robot color May 2014 - current -->
  <!-- RAL 9003 signal white (abb white), clean room robot color -->
  <!-- RAL 7032 pebble gray, controller -->
  <!-- RAL 7012 basalt gray (abb dark gray) , robot primer -->
  <!-- RAL 7021 black gray (abb black) , robot with dark link color -->
  <!-- Other robot colours available, but not limited too. -->
  <!-- RAL 3001 signal red -->
  <!-- RAL 3002 carmine red -->
  <!-- RAL 5002 ultramarine blue -->
  <!-- RAL 5015 sky blue -->
  <!-- RAL 6002 leaf green -->
  <!-- RAL 9002 gray white -->
  <!-- RAL 9010 pure white -->
  <!-- approximations -->
  <!-- yellow, collision model -->
  <!-- link list -->
  <link name="base_link">
    <visual>
      <origin rpy="0 0 0" xyz="0 0 0"/>
      <geometry>
        <mesh filename="package://abb_irb2400_support/meshes/irb2400/visual/base_link.dae"/>
      </geometry>
      <material name="">
        <color rgba="0.7372549 0.3490196 0.1607843 1"/>
      </material>
    </visual>
    <collision>
      <geometry>
        <mesh filename="package://abb_irb2400_support/meshes/irb2400/collision/base_link.stl"/>
      </geometry>
      <material name="">
        <color rgba="1 1 0 1"/>
      </material>
    </collision>
  </link>
  <link name="link_1">
    <visual>
      <origin rpy="0 0 0" xyz="0 0 0"/>
      <geometry>
        <mesh filename="package://abb_irb2400_support/meshes/irb2400/visual/link_1.dae"/>
      </geometry>
      <material name="">
        <color rgba="0.7372549 0.3490196 0.1607843 1"/>
      </material>
    </visual>
    <collision>
      <origin rpy="0 0 0" xyz="0 0 0"/>
      <geometry>
        <mesh filename="package://abb_irb2400_support/meshes/irb2400/collision/link_1.stl"/>
      </geometry>
      <material name="">
        <color rgba="1 1 0 1"/>
      </material>
    </collision>
  </link>
  <link name="link_2">
    <visual>
      <origin rpy="0 0 0" xyz="0 0 0"/>
      <geometry>
        <mesh filename="package://abb_irb2400_support/meshes/irb2400/visual/link_2.dae"/>
      </geometry>
      <material name="">
        <color rgba="0.7372549 0.3490196 0.1607843 1"/>
      </material>
    </visual>
    <collision>
      <origin rpy="0 0 0" xyz="0 0 0"/>
      <geometry>
        <mesh filename="package://abb_irb2400_support/meshes/irb2400/collision/link_2_whole.stl"/>
      </geometry>
      <material name="">
        <color rgba="1 1 0 1"/>
      </material>
    </collision>
  </link>
  <link name="link_3">
    <visual>
      <origin rpy="0 0 0" xyz="0 0 0"/>
      <geometry>
        <mesh filename="package://abb_irb2400_support/meshes/irb2400/visual/link_3.dae"/>
      </geometry>
      <material name="">
        <color rgba="0.7372549 0.3490196 0.1607843 1"/>
      </material>
    </visual>
    <collision>
      <origin rpy="0 0 0" xyz="0 0 0"/>
      <geometry>
        <mesh filename="package://abb_irb2400_support/meshes/irb2400/collision/link_3.stl"/>
      </geometry>
      <material name="">
        <color rgba="1 1 0 1"/>
      </material>
    </collision>
  </link>
  <link name="link_4">
    <visual>
      <origin rpy="0 0 0" xyz="0 0 0"/>
      <geometry>
        <mesh filename="package://abb_irb2400_support/meshes/irb2400/visual/link_4.dae"/>
      </geometry>
      <material name="">
        <color rgba="0.7372549 0.3490196 0.1607843 1"/>
      </material>
    </visual>
    <collision>
      <origin rpy="0 0 0" xyz="0 0 0"/>
      <geometry>
        <mesh filename="package://abb_irb2400_support/meshes/irb2400/collision/link_4.stl"/>
      </geometry>
      <material name="">
        <color rgba="1 1 0 1"/>
      </material>
    </collision>
  </link>
  <link name="link_5">
    <visual>
      <origin rpy="0 0 0" xyz="0 0 0"/>
      <geometry>
        <mesh filename="package://abb_irb2400_support/meshes/irb2400/visual/link_5.dae"/>
      </geometry>
      <material name="">
        <color rgba="0.7372549 0.3490196 0.1607843 1"/>
      </material>
    </visual>
    <collision>
      <origin rpy="0 0 0" xyz="0 0 0"/>
      <geometry>
        <mesh filename="package://abb_irb2400_support/meshes/irb2400/collision/link_5.stl"/>
      </geometry>
      <material name="">
        <color rgba="1 1 0 1"/>
      </material>
    </collision>
  </link>
  <link name="link_6">
    <visual>
      <origin rpy="0 0 0" xyz="0 0 0"/>
      <geometry>
        <mesh filename="package://abb_irb2400_support/meshes/irb2400/visual/link_6.dae"/>
      </geometry>
      <material name="">
        <color rgba="0.1882353 0.1960784 0.2039216 1"/>
      </material>
    </visual>
    <collision>
      <origin rpy="0 0 0" xyz="0 0 0"/>
      <geometry>
        <mesh filename="package://abb_irb2400_support/meshes/irb2400/collision/link_6.stl"/>
      </geometry>
      <material name="">
        <color rgba="1 1 0 1"/>
      </material>
    </collision>
  </link>
  <link name="tool0"/>
  <!-- end of link list -->

<!--Dummy link-->
  <link name="dummy"/>

<!--  Start of Mobile Base Links-->
  <!--Chassis-->
  <link name = "chassis">
    <visual>
      <origin rpy = "3.14 0 0" xyz = "0 0 0"/>
      <geometry>
        <mesh filename="package://abb_irb2400_support/meshes/irb2400/visual/mobile_base.dae" />
      </geometry>
    </visual>
    <collision>
      <origin rpy = "3.14 0 0" xyz = "0 0 0"/>
      <geometry>
        <mesh filename="package://abb_irb2400_support/meshes/irb2400/collision/mobile_base.stl" />
      </geometry>
    </collision>
  </link>

  <!--    Right Back Wheel-->
  <link name = "right_back_wheel">
    <visual>
      <origin rpy="1.57 0 0" xyz ="0 0 0"/>
      <geometry>
        <mesh filename="package://abb_irb2400_support/meshes/irb2400/visual/wheel_mobile_base.dae" />
      </geometry>
      <material name = "Black">
        <color rgba = "0 0 0 1"/>
      </material>
    </visual>
    <collision>
      <origin rpy="1.57 0 0" xyz ="0 0 0"/>
      <geometry>
        <mesh filename="package://abb_irb2400_support/meshes/irb2400/collision/wheel_mobile_base.stl" />
      </geometry>
    </collision>
  </link>

  <!--    Right Front Wheel-->
  <link name = "right_front_wheel">
    <visual>
      <origin rpy="1.57 0 0" xyz ="0 0 0"/>
      <geometry>
        <mesh filename="package://abb_irb2400_support/meshes/irb2400/visual/wheel_mobile_base.dae" />
      </geometry>
      <material name = "Black">
        <color rgba = "0 0 0 1"/>
      </material>
    </visual>
    <collision>
      <origin rpy="1.57 0 0" xyz ="0 0 0"/>
      <geometry>
        <mesh filename="package://abb_irb2400_support/meshes/irb2400/collision/wheel_mobile_base.stl" />
      </geometry>
    </collision>
  </link>

  <!--   Left Back Wheel-->
  <link name = "left_back_wheel">
    <visual>
      <origin rpy="1.57 0 0" xyz ="0 0 0"/>
      <geometry>
        <mesh filename="package://abb_irb2400_support/meshes/irb2400/visual/wheel_mobile_base.dae" />
      </geometry>
      <material name = "Black">
        <color rgba = "0 0 0 1"/>
      </material>
    </visual>
    <collision>
      <origin rpy="1.57 0 0" xyz ="0 0 0"/>
      <geometry>
        <mesh filename="package://abb_irb2400_support/meshes/irb2400/collision/wheel_mobile_base.stl" />
      </geometry>
    </collision>
  </link>

  <!--    Left Front Wheel-->
  <link name = "left_front_wheel">
    <visual>
      <origin rpy="1.57 0 0" xyz ="0 0 0"/>
      <geometry>
        <mesh filename="package://abb_irb2400_support/meshes/irb2400/visual/wheel_mobile_base.dae" />
      </geometry>
      <material name = "Black">
        <color rgba = "0 0 0 1"/>
      </material>
    </visual>
    <collision>
      <origin rpy="1.57 0 0" xyz ="0 0 0"/>
      <geometry>
        <mesh filename="package://abb_irb2400_support/meshes/irb2400/collision/wheel_mobile_base.stl" />
      </geometry>
    </collision>
  </link>
<!--End of Mobile Base links-->

<!--  Suction Cup Start-->
  <link name = "suction_cup_end_effector">
    <visual>
      <origin rpy="0 0 0" xyz ="0 0 0.0001"/>
      <geometry>
        <mesh filename="package://abb_irb2400_support/meshes/irb2400/visual/suction_cup.dae" />
      </geometry>
      <material name = "red">
        <color rgba = "0 1 0 1"/>
      </material>
    </visual>
    <collision>
      <origin rpy="0 0 0" xyz ="0 0 0"/>
      <geometry>
        <mesh filename="package://abb_irb2400_support/meshes/irb2400/collision/suction_cup.stl" />
      </geometry>
    </collision>
  </link>
  <!-- Suction Cup End -->

  <!-- joint list -->
  <joint name="joint_1" type="revolute">
    <origin rpy="0 0 0" xyz="0 0 0"/>
    <parent link="base_link"/>
    <child link="link_1"/>
    <axis xyz="0 0 1"/>
    <limit effort="0" lower="-3.1416" upper="3.1416" velocity="2.618"/>
  </joint>
  <joint name="joint_2" type="revolute">
    <origin rpy="0 0 0" xyz="0.1 0 0.615"/>
    <parent link="link_1"/>
    <child link="link_2"/>
    <axis xyz="0 1 0"/>
    <limit effort="0" lower="-1.7453" upper="1.9199" velocity="2.618"/>
  </joint>
  <joint name="joint_3" type="revolute">
    <origin rpy="0 0 0" xyz="0 0 0.705"/>
    <parent link="link_2"/>
    <child link="link_3"/>
    <axis xyz="0 1 0"/>
    <limit effort="0" lower="-1.0472" upper="1.1345" velocity="2.618"/>
  </joint>
  <joint name="joint_4" type="revolute">
    <origin rpy="0 0 0" xyz="0.258 0 0.135"/>
    <parent link="link_3"/>
    <child link="link_4"/>
    <axis xyz="1 0 0"/>
    <limit effort="0" lower="-3.49" upper="3.49" velocity="6.2832"/>
  </joint>
  <joint name="joint_5" type="revolute">
    <origin rpy="0 0 0" xyz="0.497 0 0"/>
    <parent link="link_4"/>
    <child link="link_5"/>
    <axis xyz="0 1 0"/>
    <limit effort="0" lower="-2.0944" upper="2.0944" velocity="6.2832"/>
  </joint>
  <joint name="joint_6" type="revolute">
    <origin rpy="0 0 0" xyz="0.085 0 0"/>
    <parent link="link_5"/>
    <child link="link_6"/>
    <axis xyz="1 0 0"/>
    <limit effort="0" lower="-6.9813" upper="6.9813" velocity="7.854"/>
  </joint>
  <joint name="joint_6-tool0" type="fixed">
    <parent link="link_6"/>
    <child link="tool0"/>
    <origin rpy="0 1.57079632679 0" xyz="0 0 0"/>
  </joint>
  <!-- end of joint list -->

  <!-- Start of Mobile base joints -->
  <joint name = "left_front_wheel_joint" type = "continuous">
    <parent link = "chassis"/>
    <child link = "right_back_wheel"/>
    <origin rpy = '0 0 0' xyz="-0.535 -0.76 -0.35"/>
    <axis xyz = "0 1 0"/>
    <limit effort = "100" velocity = "100"/>
    <dynamics damping = "0.0" friction = "0.0"/>
  </joint>

  <joint name = "left_back_wheel_joint" type = "continuous">
    <parent link = "chassis"/>
    <child link = "right_front_wheel"/>
    <origin rpy = '0 0 0' xyz="0.465 -0.76 -0.35"/>
    <axis xyz = "0 1 0"/>
    <limit effort = "100" velocity = "100"/>
    <dynamics damping = "0.0" friction = "0.0"/>
  </joint>

  <joint name = "right_front_wheel_joint" type = "continuous">
    <parent link = "chassis"/>
    <child link = "left_back_wheel"/>
    <origin xyz="-0.535 0.64 -0.35" rpy = "0 0 0" />
    <axis xyz = "0 1 0"/>
    <limit effort = "100" velocity = "100"/>
    <dynamics damping = "0.0" friction = "0.0"/>
  </joint>

  <joint name = "right_back_wheel_joint" type = "continuous">
    <parent link = "chassis"/>
    <child link = "left_front_wheel"/>
    <origin rpy = '0 0 0' xyz="0.465 0.64 -0.35"/>
    <axis xyz = "0 1 0"/>
    <limit effort = "100" velocity = "100"/>
    <dynamics damping = "0.0" friction = "0.0"/>
  </joint>

<!--  End of Mobile base joints-->

<!-- Suction Cup joint -->
  <joint name="suction_to_tool0" type="fixed">
    <parent link="tool0"/>
    <child link="suction_cup_end_effector"/>
    <origin rpy="0 0 0" xyz="0 0 0"/>
  </joint>
<!--  End-->

  <joint name="dummy_joint" type="fixed">
    <parent link="dummy"/>
    <child link="chassis"/>
    <origin xyz="0.0 0.0 0.43" rpy="0 0 0" />
  </joint>

<!--  ABB robots connection to chassis base-->
  <joint name="chassis_to_base_link" type="fixed">
    <origin rpy="0 0 0" xyz="-0.2 0 0"/>
    <parent link="chassis"/>
    <child link="base_link"/>
  </joint>
</robot>

